Workbook

Sheet User_Recommendation
A1: CLOUD CARBON FOOTPRINT OPTIMIZER — USER INPUT & 3-PROVIDER COMPARISON
A2: IMPORTANT: Missing factors stay blank; no provider is recommended unless enough comparable regional data exists.
A3: User input
A4: Target country / location | B4: India
A5: Estimated workload energy (kWh) | B5: 100
A6: Comparison basis | B6: Same location-level grid factor where available
A7: Data year | B7: Use year shown in source data; current template does not assume all factors are same year
A8: Recommendation status | B8: =IF(COUNTIFS($A$13:$A$300,$B$4,$F$13:$F$300,">=0")<2,"INSUFFICIENT DATA: fewer than 2 valid provider-region estimates for this location","See eligible rows below; recommendation only valid where factors are comparable")
A10: How to use
A11: 1) Select a country and enter estimated workload energy in kWh. 2) Filter the table's Country column to the selected country. 3) Compare emissions only for rows with a numeric grid factor. 4) Lowest emissions is a location-grid estimate, not a provider's full reported footprint.
A12: Country | B12: Provider | C12: Region code | D12: Region name | E12: Grid intensity (gCO₂e/kWh) | F12: Estimated emissions (kgCO₂e) | G12: Data status | H12: Interpretation / notes
A13: India | B13: AWS | C13: ap-south-1 | D13: Mumbai | F13: =IF(OR(E13="",NOT(ISNUMBER(E13)),NOT(ISNUMBER($B$5))),"",E13*$B$5/1000) | G13: Metadata only - no verified matching grid value | H13: No sufficiently verified same-location grid value in the current workbook; do not estimate or substitute.
A14: India | B14: AWS | C14: ap-south-2 | D14: Hyderabad | F14: =IF(OR(E14="",NOT(ISNUMBER(E14)),NOT(ISNUMBER($B$5))),"",E14*$B$5/1000) | G14: Metadata only - no verified matching grid value | H14: No sufficiently verified same-location grid value in the current workbook; do not estimate or substitute.
A15: Singapore | B15: AWS | C15: ap-southeast-1 | D15: Singapore | E15: 366 | F15: =IF(OR(E15="",NOT(ISNUMBER(E15)),NOT(ISNUMBER($B$5))),"",E15*$B$5/1000) | G15: Published grid value mapped (location proxy) | H15: Mapped published grid-intensity value from GCP location Singapore (asia-southeast1); used as location-level grid proxy only, not AWS/Azure provider emissions
A16: United States | B16: AWS | C16: us-east-1 | D16: N. Virginia | E16: 343 | F16: =IF(OR(E16="",NOT(ISNUMBER(E16)),NOT(ISNUMBER($B$5))),"",E16*$B$5/1000) | G16: Published grid value mapped (location proxy) | H16: Mapped published grid-intensity value from GCP location Northern Virginia (us-east4); used as location-level grid proxy only, not AWS/Azure provider emissions
A17: United States | B17: AWS | C17: us-west-2 | D17: Oregon | E17: 98 | F17: =IF(OR(E17="",NOT(ISNUMBER(E17)),NOT(ISNUMBER($B$5))),"",E17*$B$5/1000) | G17: Published grid value mapped (location proxy) | H17: Mapped published grid-intensity value from GCP location Oregon (us-west1); used as location-level grid proxy only, not AWS/Azure provider emissions
A18: India | B18: Azure | C18: centralindia | D18: Pune | F18: =IF(OR(E18="",NOT(ISNUMBER(E18)),NOT(ISNUMBER($B$5))),"",E18*$B$5/1000) | G18: Metadata only - no verified matching grid value | H18: No sufficiently verified same-location grid value in the current workbook; do not estimate or substitute.
A19: India | B19: Azure | C19: indiasouthcentral | D19: Hyderabad | F19: =IF(OR(E19="",NOT(ISNUMBER(E19)),NOT(ISNUMBER($B$5))),"",E19*$B$5/1000) | G19: Metadata only - no verified matching grid value | H19: No sufficiently verified same-location grid value in the current workbook; do not estimate or substitute.
A20: India | B20: Azure | C20: southindia | D20: Chennai | F20: =IF(OR(E20="",NOT(ISNUMBER(E20)),NOT(ISNUMBER($B$5))),"",E20*$B$5/1000) | G20: Metadata only - no verified matching grid value | H20: No sufficiently verified same-location grid value in the current workbook; do not estimate or substitute.
A21: India | B21: Azure | C21: westindia | D21: Mumbai | E21: 598 | F21: =IF(OR(E21="",NOT(ISNUMBER(E21)),NOT(ISNUMBER($B$5))),"",E21*$B$5/1000) | G21: Metadata only - no verified matching grid value | H21: Mapped published grid-intensity value from GCP location Mumbai (asia-south1); used as location-level grid proxy only, not AWS/Azure provider emissions
A22: Singapore | B22: Azure | C22: southeastasia | D22: Singapore | E22: 366 | F22: =IF(OR(E22="",NOT(ISNUMBER(E22)),NOT(ISNUMBER($B$5))),"",E22*$B$5/1000) | G22: Metadata only - no verified matching grid value | H22: Mapped published grid-intensity value from GCP location Singapore (asia-southeast1); used as location-level grid proxy only, not AWS/Azure provider emissions
A23: United States | B23: Azure | C23: eastus | D23: Virginia | F23: =IF(OR(E23="",NOT(ISNUMBER(E23)),NOT(ISNUMBER($B$5))),"",E23*$B$5/1000) | G23: Metadata only - no verified matching grid value | H23: No sufficiently verified same-location grid value in the current workbook; do not estimate or substitute.
A24: India | B24: GCP | C24: asia-south1 | D24: Mumbai | E24: 598 | F24: =IF(OR(E24="",NOT(ISNUMBER(E24)),NOT(ISNUMBER($B$5))),"",E24*$B$5/1000) | G24: Current | H24: Provider-published 2025 regional metric
A25: India | B25: GCP | C25: asia-south2 | D25: Delhi | E25: 473 | F25: =IF(OR(E25="",NOT(ISNUMBER(E25)),NOT(ISNUMBER($B$5))),"",E25*$B$5/1000) | G25: Current | H25: Provider-published 2025 regional metric
A26: Singapore | B26: GCP | C26: asia-southeast1 | D26: Singapore | E26: 366 | F26: =IF(OR(E26="",NOT(ISNUMBER(E26)),NOT(ISNUMBER($B$5))),"",E26*$B$5/1000) | G26: Current | H26: Provider-published 2025 regional metric
A27: United States | B27: GCP | C27: us-east4 | D27: Northern Virginia | E27: 343 | F27: =IF(OR(E27="",NOT(ISNUMBER(E27)),NOT(ISNUMBER($B$5))),"",E27*$B$5/1000) | G27: Current | H27: Provider-published 2025 regional metric
A28: United States | B28: GCP | C28: us-central1 | D28: Iowa | E28: 432 | F28: =IF(OR(E28="",NOT(ISNUMBER(E28)),NOT(ISNUMBER($B$5))),"",E28*$B$5/1000) | G28: Current | H28: Provider-published 2025 regional metric
A29: Finland | B29: GCP | C29: europe-north1 | D29: Finland | E29: 30 | F29: =IF(OR(E29="",NOT(ISNUMBER(E29)),NOT(ISNUMBER($B$5))),"",E29*$B$5/1000) | G29: Current | H29: Provider-published 2025 regional metric
A30: Sweden | B30: GCP | C30: europe-north2 | D30: Stockholm | E30: 19 | F30: =IF(OR(E30="",NOT(ISNUMBER(E30)),NOT(ISNUMBER($B$5))),"",E30*$B$5/1000) | G30: Current | H30: Provider-published 2025 regional metric
A31: South Africa | B31: AWS | C31: af-south-1 | D31: Africa (Cape Town) | F31: =IF(OR(E31="",NOT(ISNUMBER(E31)),NOT(ISNUMBER($B$5))),"",E31*$B$5/1000) | G31: Region metadata only - no verified location grid factor | H31: Option 1 requires a verified grid-intensity factor for this location and matching period. No value inferred from country or another provider.
A32: Hong Kong | B32: AWS | C32: ap-east-1 | D32: Asia Pacific (Hong Kong) | F32: =IF(OR(E32="",NOT(ISNUMBER(E32)),NOT(ISNUMBER($B$5))),"",E32*$B$5/1000) | G32: Region metadata only - no verified location grid factor | H32: Option 1 requires a verified grid-intensity factor for this location and matching period. No value inferred from country or another provider.
A33: Taiwan | B33: AWS | C33: ap-east-2 | D33: Asia Pacific (Taipei) | F33: =IF(OR(E33="",NOT(ISNUMBER(E33)),NOT(ISNUMBER($B$5))),"",E33*$B$5/1000) | G33: Region metadata only - no verified location grid factor | H33: Option 1 requires a verified grid-intensity factor for this location and matching period. No value inferred from country or another provider.
A34: Japan | B34: AWS | C34: ap-northeast-1 | D34: Asia Pacific (Tokyo) | F34: =IF(OR(E34="",NOT(ISNUMBER(E34)),NOT(ISNUMBER($B$5))),"",E34*$B$5/1000) | G34: Region metadata only - no verified location grid factor | H34: Option 1 requires a verified grid-intensity factor for this location and matching period. No value inferred from country or another provider.
A35: South Korea | B35: AWS | C35: ap-northeast-2 | D35: Asia Pacific (Seoul) | F35: =IF(OR(E35="",NOT(ISNUMBER(E35)),NOT(ISNUMBER($B$5))),"",E35*$B$5/1000) | G35: Region metadata only - no verified location grid factor | H35: Option 1 requires a verified grid-intensity factor for this location and matching period. No value inferred from country or another provider.
A36: Japan | B36: AWS | C36: ap-northeast-3 | D36: Asia Pacific (Osaka) | F36: =IF(OR(E36="",NOT(ISNUMBER(E36)),NOT(ISNUMBER($B$5))),"",E36*$B$5/1000) | G36: Region metadata only - no verified location grid factor | H36: Option 1 requires a verified grid-intensity factor for this location and matching period. No value inferred from country or another provider.
A37: Australia | B37: AWS | C37: ap-southeast-2 | D37: Asia Pacific (Sydney) | F37: =IF(OR(E37="",NOT(ISNUMBER(E37)),NOT(ISNUMBER($B$5))),"",E37*$B$5/1000) | G37: Region metadata only - no verified location grid factor | H37: Option 1 requires a verified grid-intensity factor for this location and matching period. No value inferred from country or another provider.
A38: Indonesia | B38: AWS | C38: ap-southeast-3 | D38: Asia Pacific (Jakarta) | F38: =IF(OR(E38="",NOT(ISNUMBER(E38)),NOT(ISNUMBER($B$5))),"",E38*$B$5/1000) | G38: Region metadata only - no verified location grid factor | H38: Option 1 requires a verified grid-intensity factor for this location and matching period. No value inferred from country or another provider.
A39: Australia | B39: AWS | C39: ap-southeast-4 | D39: Asia Pacific (Melbourne) | F39: =IF(OR(E39="",NOT(ISNUMBER(E39)),NOT(ISNUMBER($B$5))),"",E39*$B$5/1000) | G39: Region metadata only - no verified location grid factor | H39: Option 1 requires a verified grid-intensity factor for this location and matching period. No value inferred from country or another provider.
A40: Malaysia | B40: AWS | C40: ap-southeast-5 | D40: Asia Pacific (Malaysia) | F40: =IF(OR(E40="",NOT(ISNUMBER(E40)),NOT(ISNUMBER($B$5))),"",E40*$B$5/1000) | G40: Region metadata only - no verified location grid factor | H40: Option 1 requires a verified grid-intensity factor for this location and matching period. No value inferred from country or another provider.
A41: New Zealand | B41: AWS | C41: ap-southeast-6 | D41: Asia Pacific (New Zealand) | F41: =IF(OR(E41="",NOT(ISNUMBER(E41)),NOT(ISNUMBER($B$5))),"",E41*$B$5/1000) | G41: Region metadata only - no verified location grid factor | H41: Option 1 requires a verified grid-intensity factor for this location and matching period. No value inferred from country or another provider.
...

Sheet Provider_Coverage_Summary
A1: Provider | B1: Region rows | C1: Rows with grid intensity | D1: Rows missing intensity | E1: Coverage % | F1: Interpretation
A2: AWS | B2: 34 | C2: 3 | D2: 31 | E2: 0.088235294 | F2: Values may be published regional metrics or labelled location proxies; do not compare provider emissions. Missing factors must be sourced before region can be ranked.
A3: Azure | B3: 59 | C3: 2 | D3: 57 | E3: 0.033898305 | F3: Values may be published regional metrics or labelled location proxies; do not compare provider emissions. Missing factors must be sourced before region can be ranked.
A4: GCP | B4: 44 | C4: 44 | D4: 0 | E4: 1 | F4: Values may be published regional metrics or labelled location proxies; do not compare provider emissions. Missing factors must be sourced before region can be ranked.

Sheet Option1_Region_Comparison
A1: Provider | B1: Region_Code | C1: Region | D1: Country | E1: Grid_Intensity_gCO2e_per_kWh | F1: Grid_Intensity_kgCO2e_per_kWh | G1: Data_Status | H1: Data_Type | I1: Source_or_Method | J1: Can_Calculate_CO2e | K1: Calculation_Formula | L1: Notes
A2: GCP | B2: africa-south1 | C2: Johannesburg | D2: South Africa | E2: 641 | F2: 0.641 | G2: 2025 published data | H2: Published GCP regional metric | I2: Google Cloud regional carbon page (2025 data) | J2: YES | K2: Energy_kWh × grid intensity (gCO₂e/kWh) | L2: Official Google Cloud regional value. Not directly comparable to AWS/Azure provider-specific emissions.
A3: GCP | B3: asia-east1 | C3: Taiwan | D3: Taiwan | E3: 428 | F3: 0.428 | G3: 2025 published data | H3: Published GCP regional metric | I3: Google Cloud regional carbon page (2025 data) | J3: YES | K3: Energy_kWh × grid intensity (gCO₂e/kWh) | L3: Official Google Cloud regional value. Not directly comparable to AWS/Azure provider-specific emissions.
A4: GCP | B4: asia-east2 | C4: Hong Kong | D4: Hong Kong | E4: 489 | F4: 0.489 | G4: 2025 published data | H4: Published GCP regional metric | I4: Google Cloud regional carbon page (2025 data) | J4: YES | K4: Energy_kWh × grid intensity (gCO₂e/kWh) | L4: Official Google Cloud regional value. Not directly comparable to AWS/Azure provider-specific emissions.
A5: GCP | B5: asia-northeast1 | C5: Tokyo | D5: Japan | E5: 449 | F5: 0.449 | G5: 2025 published data | H5: Published GCP regional metric | I5: Google Cloud regional carbon page (2025 data) | J5: YES | K5: Energy_kWh × grid intensity (gCO₂e/kWh) | L5: Official Google Cloud regional value. Not directly comparable to AWS/Azure provider-specific emissions.
A6: GCP | B6: asia-northeast2 | C6: Osaka | D6: Japan | E6: 299 | F6: 0.299 | G6: 2025 published data | H6: Published GCP regional metric | I6: Google Cloud regional carbon page (2025 data) | J6: YES | K6: Energy_kWh × grid intensity (gCO₂e/kWh) | L6: Official Google Cloud regional value. Not directly comparable to AWS/Azure provider-specific emissions.
A7: GCP | B7: asia-northeast3 | C7: Seoul | D7: South Korea | E7: 359 | F7: 0.359 | G7: 2025 published data | H7: Published GCP regional metric | I7: Google Cloud regional carbon page (2025 data) | J7: YES | K7: Energy_kWh × grid intensity (gCO₂e/kWh) | L7: Official Google Cloud regional value. Not directly comparable to AWS/Azure provider-specific emissions.
A8: GCP | B8: asia-south1 | C8: Mumbai | D8: India | E8: 598 | F8: 0.598 | G8: 2025 published data | H8: Published GCP regional metric | I8: Google Cloud regional carbon page (2025 data) | J8: YES | K8: Energy_kWh × grid intensity (gCO₂e/kWh) | L8: Official Google Cloud regional value. Not directly comparable to AWS/Azure provider-specific emissions.
A9: GCP | B9: asia-south2 | C9: Delhi | D9: India | E9: 473 | F9: 0.473 | G9: 2025 published data | H9: Published GCP regional metric | I9: Google Cloud regional carbon page (2025 data) | J9: YES | K9: Energy_kWh × grid intensity (gCO₂e/kWh) | L9: Official Google Cloud regional value. Not directly comparable to AWS/Azure provider-specific emissions.
A10: GCP | B10: asia-southeast1 | C10: Singapore | D10: Singapore | E10: 366 | F10: 0.366 | G10: 2025 published data | H10: Published GCP regional metric | I10: Google Cloud regional carbon page (2025 data) | J10: YES | K10: Energy_kWh × grid intensity (gCO₂e/kWh) | L10: Official Google Cloud regional value. Not directly comparable to AWS/Azure provider-specific emissions.
A11: GCP | B11: asia-southeast2 | C11: Jakarta | D11: Indonesia | E11: 588 | F11: 0.588 | G11: 2025 published data | H11: Published GCP regional metric | I11: Google Cloud regional carbon page (2025 data) | J11: YES | K11: Energy_kWh × grid intensity (gCO₂e/kWh) | L11: Official Google Cloud regional value. Not directly comparable to AWS/Azure provider-specific emissions.
A12: GCP | B12: australia-southeast1 | C12: Sydney | D12: Australia | E12: 468 | F12: 0.468 | G12: 2025 published data | H12: Published GCP regional metric | I12: Google Cloud regional carbon page (2025 data) | J12: YES | K12: Energy_kWh × grid intensity (gCO₂e/kWh) | L12: Official Google Cloud regional value. Not directly comparable to AWS/Azure provider-specific emissions.
A13: GCP | B13: australia-southeast2 | C13: Melbourne | D13: Australia | E13: 416 | F13: 0.416 | G13: 2025 published data | H13: Published GCP regional metric | I13: Google Cloud regional carbon page (2025 data) | J13: YES | K13: Energy_kWh × grid intensity (gCO₂e/kWh) | L13: Official Google Cloud regional value. Not directly comparable to AWS/Azure provider-specific emissions.
... A45: GCP | B45: us-west4 | C45: Las Vegas | D45: United States | E45: 360 | F45: 0.36 | G45: 2025 published data | H45: Published GCP regional metric | I45: Google Cloud regional carbon page (2025 data) | J45: YES | K45: Energy_kWh × grid intensity (gCO₂e/kWh) | L45: Official Google Cloud regional value. Not directly comparable to AWS/Azure provider-specific emissions.
A46: AWS | B46: ap-south-1 | C46: Mumbai | D46: India | G46: Metadata only - no verified matching grid value | H46: Unavailable - left blank | J46: NO | K46: Unavailable until verified grid intensity is supplied | L46: No sufficiently verified same-location grid value in the current workbook; do not estimate or substitute.
A47: AWS | B47: ap-south-2 | C47: Hyderabad | D47: India | G47: Metadata only - no verified matching grid value | H47: Unavailable - left blank | J47: NO | K47: Unavailable until verified grid intensity is supplied | L47: No sufficiently verified same-location grid value in the current workbook; do not estimate or substitute.
A48: AWS | B48: ap-southeast-1 | C48: Singapore | D48: Singapore | E48: 366 | F48: 0.366 | G48: Published grid value mapped (location proxy) | H48: Mapped location-level grid proxy (not provider emissions) | I48: Google Cloud regional carbon page (2025 data) | J48: YES | K48: Energy_kWh × grid intensity (gCO₂e/kWh) | L48: Location-level grid proxy; not provider-reported emissions. Verify exact geography and year before final use.
A49: AWS | B49: us-east-1 | C49: N. Virginia | D49: United States | E49: 343 | F49: 0.343 | G49: Published grid value mapped (location proxy) | H49: Mapped location-level grid proxy (not provider emissions) | I49: Google Cloud regional carbon page (2025 data) | J49: YES | K49: Energy_kWh × grid intensity (gCO₂e/kWh) | L49: Location-level grid proxy; not provider-reported emissions. Verify exact geography and year before final use.
A50: AWS | B50: us-west-2 | C50: Oregon | D50: United States | E50: 98 | F50: 0.098 | G50: Published grid value mapped (location proxy) | H50: Mapped location-level grid proxy (not provider emissions) | I50: Google Cloud regional carbon page (2025 data) | J50: YES | K50: Energy_kWh × grid intensity (gCO₂e/kWh) | L50: Location-level grid proxy; not provider-reported emissions. Verify exact geography and year before final use.
A51: Azure | B51: centralindia | C51: Pune | D51: India | G51: Metadata only - no verified matching grid value | H51: Unavailable - left blank | J51: NO | K51: Unavailable until verified grid intensity is supplied | L51: No sufficiently verified same-location grid value in the current workbook; do not estimate or substitute.
A52: Azure | B52: indiasouthcentral | C52: Hyderabad | D52: India | G52: Metadata only - no verified matching grid value | H52: Unavailable - left blank | J52: NO | K52: Unavailable until verified grid intensity is supplied | L52: No sufficiently verified same-location grid value in the current workbook; do not estimate or substitute.
A53: Azure | B53: southindia | C53: Chennai | D53: India | G53: Metadata only - no verified matching grid value | H53: Unavailable - left blank | J53: NO | K53: Unavailable until verified grid intensity is supplied | L53: No sufficiently verified same-location grid value in the current workbook; do not estimate or substitute.
A54: Azure | B54: westindia | C54: Mumbai | D54: India | E54: 598 | F54: 0.598 | G54: Published grid value mapped (location proxy) | H54: Mapped location-level grid proxy (not provider emissions) | I54: Google Cloud regional carbon page (2025 data) | J54: YES | K54: Energy_kWh × grid intensity (gCO₂e/kWh) | L54: Location-level grid proxy; not provider-reported emissions. Verify exact geography and year before final use.
A55: Azure | B55: southeastasia | C55: Singapore | D55: Singapore | E55: 366 | F55: 0.366 | G55: Published grid value mapped (location proxy) | H55: Mapped location-level grid proxy (not provider emissions) | I55: Google Cloud regional carbon page (2025 data) | J55: YES | K55: Energy_kWh × grid intensity (gCO₂e/kWh) | L55: Location-level grid proxy; not provider-reported emissions. Verify exact geography and year before final use.
A56: Azure | B56: eastus | C56: Virginia | D56: United States | G56: Metadata only - no verified matching grid value | H56: Unavailable - left blank | J56: NO | K56: Unavailable until verified grid intensity is supplied | L56: No sufficiently verified same-location grid value in the current workbook; do not estimate or substitute.
A57: AWS | B57: af-south-1 | C57: Africa (Cape Town) | D57: South Africa | G57: Region metadata only - no verified location grid factor | H57: Unavailable - left blank | J57: NO | K57: Unavailable until verified grid intensity is supplied | L57: Option 1 requires a verified grid-intensity factor for this location and matching period. No value inferred from country or another provider.
A58: AWS | B58: ap-east-1 | C58: Asia Pacific (Hong Kong) | D58: Hong Kong | G58: Region metadata only - no verified location grid factor | H58: Unavailable - left blank | J58: NO | K58: Unavailable until verified grid intensity is supplied | L58: Option 1 requires a verified grid-intensity factor for this location and matching period. No value inferred from country or another provider.
A59: AWS | B59: ap-east-2 | C59: Asia Pacific (Taipei) | D59: Taiwan | G59: Region metadata only - no verified location grid factor | H59: Unavailable - left blank | J59: NO | K59: Unavailable until verified grid intensity is supplied | L59: Option 1 requires a verified grid-intensity factor for this location and matching period. No value inferred from country or another provider.
A60: AWS | B60: ap-northeast-1 | C60: Asia Pacific (Tokyo) | D60: Japan | G60: Region metadata only - no verified location grid factor | H60: Unavailable - left blank | J60: NO | K60: Unavailable until verified grid intensity is supplied | L60: Option 1 requires a verified grid-intensity factor for this location and matching period. No value inferred from country or another provider.
A61: AWS | B61: ap-northeast-2 | C61: Asia Pacific (Seoul) | D61: South Korea | G61: Region metadata only - no verified location grid factor | H61: Unavailable - left blank | J61: NO | K61: Unavailable until verified grid intensity is supplied | L61: Option 1 requires a verified grid-intensity factor for this location and matching period. No value inferred from country or another provider.
A62: AWS | B62: ap-northeast-3 | C62: Asia Pacific (Osaka) | D62: Japan | G62: Region metadata only - no verified location grid factor | H62: Unavailable - left blank | J62: NO | K62: Unavailable until verified grid intensity is supplied | L62: Option 1 requires a verified grid-intensity factor for this location and matching period. No value inferred from country or another provider.
A63: AWS | B63: ap-southeast-2 | C63: Asia Pacific (Sydney) | D63: Australia | G63: Region metadata only - no verified location grid factor | H63: Unavailable - left blank | J63: NO | K63: Unavailable until verified grid intensity is supplied | L63: Option 1 requires a verified grid-intensity factor for this location and matching period. No value inferred from country or another provider.
A64: AWS | B64: ap-southeast-3 | C64: Asia Pacific (Jakarta) | D64: Indonesia | G64: Region metadata only - no verified location grid factor | H64: Unavailable - left blank | J64: NO | K64: Unavailable until verified grid intensity is supplied | L64: Option 1 requires a verified grid-intensity factor for this location and matching period. No value inferred from country or another provider.
A65: AWS | B65: ap-southeast-4 | C65: Asia Pacific (Melbourne) | D65: Australia | G65: Region metadata only - no verified location grid factor | H65: Unavailable - left blank | J65: NO | K65: Unavailable until verified grid intensity is supplied | L65: Option 1 requires a verified grid-intensity factor for this location and matching period. No value inferred from country or another provider.
A66: AWS | B66: ap-southeast-5 | C66: Asia Pacific (Malaysia) | D66: Malaysia | G66: Region metadata only - no verified location grid factor | H66: Unavailable - left blank | J66: NO | K66: Unavailable until verified grid intensity is supplied | L66: Option 1 requires a verified grid-intensity factor for this location and matching period. No value inferred from country or another provider.
A67: AWS | B67: ap-southeast-6 | C67: Asia Pacific (New Zealand) | D67: New Zealand | G67: Region metadata only - no verified location grid factor | H67: Unavailable - left blank | J67: NO | K67: Unavailable until verified grid intensity is supplied | L67: Option 1 requires a verified grid-intensity factor for this location and matching period. No value inferred from country or another provider.
... A138: Azure | B138: taiwannorth | C138: Taiwan North | D138: Taiwan | G138: Region metadata only - no verified location grid factor | H138: Unavailable - left blank | J138: NO | K138: Unavailable until verified grid intensity is supplied | L138: Option 1 requires a verified grid-intensity factor for this location and matching period. No value inferred from country or another provider.

Sheet Final_Calculation
A1: Record_ID | B1: Workload_Type | C1: Provider | D1: Region_Code | E1: Region | F1: Country | G1: CPU_Utilization_% | H1: RAM_GB | I1: Storage_GB | J1: Runtime_Hours | K1: VM_Count | L1: Carbon_Intensity_gCO2e_per_kWh | M1: Energy_kWh_estimated | N1: CO2e_g_estimated | O1: CO2e_kg_estimated | P1: CFE_% | Q1: Calculation_Status | R1: Emissions_Source_Type
A2: =Merged_Dataset!A2 | B2: =Merged_Dataset!B2 | C2: =Merged_Dataset!H2 | D2: =Merged_Dataset!I2 | E2: =Merged_Dataset!J2 | F2: =Merged_Dataset!K2 | G2: =Merged_Dataset!C2 | H2: =Merged_Dataset!D2 | I2: =Merged_Dataset!E2 | J2: =Merged_Dataset!F2 | K2: =Merged_Dataset!G2 | L2: =Merged_Dataset!M2 | M2: =Merged_Dataset!S2 | N2: =Merged_Dataset!T2 | O2: =Merged_Dataset!U2 | P2: =Merged_Dataset!R2 | Q2: =Merged_Dataset!V2 | R2: =IF(O2="","Estimated calculation unavailable until coefficients and carbon intensity are supplied","Grid-intensity-based estimate; not provider-reported emissions")
A3: =Merged_Dataset!A3 | B3: =Merged_Dataset!B3 | C3: =Merged_Dataset!H3 | D3: =Merged_Dataset!I3 | E3: =Merged_Dataset!J3 | F3: =Merged_Dataset!K3 | G3: =Merged_Dataset!C3 | H3: =Merged_Dataset!D3 | I3: =Merged_Dataset!E3 | J3: =Merged_Dataset!F3 | K3: =Merged_Dataset!G3 | L3: =Merged_Dataset!M3 | M3: =Merged_Dataset!S3 | N3: =Merged_Dataset!T3 | O3: =Merged_Dataset!U3 | P3: =Merged_Dataset!R3 | Q3: =Merged_Dataset!V3 | R3: =IF(O3="","Estimated calculation unavailable until coefficients and carbon intensity are supplied","Grid-intensity-based estimate; not provider-reported emissions")
A4: =Merged_Dataset!A4 | B4: =Merged_Dataset!B4 | C4: =Merged_Dataset!H4 | D4: =Merged_Dataset!I4 | E4: =Merged_Dataset!J4 | F4: =Merged_Dataset!K4 | G4: =Merged_Dataset!C4 | H4: =Merged_Dataset!D4 | I4: =Merged_Dataset!E4 | J4: =Merged_Dataset!F4 | K4: =Merged_Dataset!G4 | L4: =Merged_Dataset!M4 | M4: =Merged_Dataset!S4 | N4: =Merged_Dataset!T4 | O4: =Merged_Dataset!U4 | P4: =Merged_Dataset!R4 | Q4: =Merged_Dataset!V4 | R4: =IF(O4="","Estimated calculation unavailable until coefficients and carbon intensity are supplied","Grid-intensity-based estimate; not provider-reported emissions")
A5: =Merged_Dataset!A5 | B5: =Merged_Dataset!B5 | C5: =Merged_Dataset!H5 | D5: =Merged_Dataset!I5 | E5: =Merged_Dataset!J5 | F5: =Merged_Dataset!K5 | G5: =Merged_Dataset!C5 | H5: =Merged_Dataset!D5 | I5: =Merged_Dataset!E5 | J5: =Merged_Dataset!F5 | K5: =Merged_Dataset!G5 | L5: =Merged_Dataset!M5 | M5: =Merged_Dataset!S5 | N5: =Merged_Dataset!T5 | O5: =Merged_Dataset!U5 | P5: =Merged_Dataset!R5 | Q5: =Merged_Dataset!V5 | R5: =IF(O5="","Estimated calculation unavailable until coefficients and carbon intensity are supplied","Grid-intensity-based estimate; not provider-reported emissions")
A6: =Merged_Dataset!A6 | B6: =Merged_Dataset!B6 | C6: =Merged_Dataset!H6 | D6: =Merged_Dataset!I6 | E6: =Merged_Dataset!J6 | F6: =Merged_Dataset!K6 | G6: =Merged_Dataset!C6 | H6: =Merged_Dataset!D6 | I6: =Merged_Dataset!E6 | J6: =Merged_Dataset!F6 | K6: =Merged_Dataset!G6 | L6: =Merged_Dataset!M6 | M6: =Merged_Dataset!S6 | N6: =Merged_Dataset!T6 | O6: =Merged_Dataset!U6 | P6: =Merged_Dataset!R6 | Q6: =Merged_Dataset!V6 | R6: =IF(O6="","Estimated calculation unavailable until coefficients and carbon intensity are supplied","Grid-intensity-based estimate; not provider-reported emissions")
A7: =Merged_Dataset!A7 | B7: =Merged_Dataset!B7 | C7: =Merged_Dataset!H7 | D7: =Merged_Dataset!I7 | E7: =Merged_Dataset!J7 | F7: =Merged_Dataset!K7 | G7: =Merged_Dataset!C7 | H7: =Merged_Dataset!D7 | I7: =Merged_Dataset!E7 | J7: =Merged_Dataset!F7 | K7: =Merged_Dataset!G7 | L7: =Merged_Dataset!M7 | M7: =Merged_Dataset!S7 | N7: =Merged_Dataset!T7 | O7: =Merged_Dataset!U7 | P7: =Merged_Dataset!R7 | Q7: =Merged_Dataset!V7 | R7: =IF(O7="","Estimated calculation unavailable until coefficients and carbon intensity are supplied","Grid-intensity-based estimate; not provider-reported emissions")
A8: =Merged_Dataset!A8 | B8: =Merged_Dataset!B8 | C8: =Merged_Dataset!H8 | D8: =Merged_Dataset!I8 | E8: =Merged_Dataset!J8 | F8: =Merged_Dataset!K8 | G8: =Merged_Dataset!C8 | H8: =Merged_Dataset!D8 | I8: =Merged_Dataset!E8 | J8: =Merged_Dataset!F8 | K8: =Merged_Dataset!G8 | L8: =Merged_Dataset!M8 | M8: =Merged_Dataset!S8 | N8: =Merged_Dataset!T8 | O8: =Merged_Dataset!U8 | P8: =Merged_Dataset!R8 | Q8: =Merged_Dataset!V8 | R8: =IF(O8="","Estimated calculation unavailable until coefficients and carbon intensity are supplied","Grid-intensity-based estimate; not provider-reported emissions")
A9: =Merged_Dataset!A9 | B9: =Merged_Dataset!B9 | C9: =Merged_Dataset!H9 | D9: =Merged_Dataset!I9 | E9: =Merged_Dataset!J9 | F9: =Merged_Dataset!K9 | G9: =Merged_Dataset!C9 | H9: =Merged_Dataset!D9 | I9: =Merged_Dataset!E9 | J9: =Merged_Dataset!F9 | K9: =Merged_Dataset!G9 | L9: =Merged_Dataset!M9 | M9: =Merged_Dataset!S9 | N9: =Merged_Dataset!T9 | O9: =Merged_Dataset!U9 | P9: =Merged_Dataset!R9 | Q9: =Merged_Dataset!V9 | R9: =IF(O9="","Estimated calculation unavailable until coefficients and carbon intensity are supplied","Grid-intensity-based estimate; not provider-reported emissions")
A10: =Merged_Dataset!A10 | B10: =Merged_Dataset!B10 | C10: =Merged_Dataset!H10 | D10: =Merged_Dataset!I10 | E10: =Merged_Dataset!J10 | F10: =Merged_Dataset!K10 | G10: =Merged_Dataset!C10 | H10: =Merged_Dataset!D10 | I10: =Merged_Dataset!E10 | J10: =Merged_Dataset!F10 | K10: =Merged_Dataset!G10 | L10: =Merged_Dataset!M10 | M10: =Merged_Dataset!S10 | N10: =Merged_Dataset!T10 | O10: =Merged_Dataset!U10 | P10: =Merged_Dataset!R10 | Q10: =Merged_Dataset!V10 | R10: =IF(O10="","Estimated calculation unavailable until coefficients and carbon intensity are supplied","Grid-intensity-based estimate; not provider-reported emissions")
A11: =Merged_Dataset!A11 | B11: =Merged_Dataset!B11 | C11: =Merged_Dataset!H11 | D11: =Merged_Dataset!I11 | E11: =Merged_Dataset!J11 | F11: =Merged_Dataset!K11 | G11: =Merged_Dataset!C11 | H11: =Merged_Dataset!D11 | I11: =Merged_Dataset!E11 | J11: =Merged_Dataset!F11 | K11: =Merged_Dataset!G11 | L11: =Merged_Dataset!M11 | M11: =Merged_Dataset!S11 | N11: =Merged_Dataset!T11 | O11: =Merged_Dataset!U11 | P11: =Merged_Dataset!R11 | Q11: =Merged_Dataset!V11 | R11: =IF(O11="","Estimated calculation unavailable until coefficients and carbon intensity are supplied","Grid-intensity-based estimate; not provider-reported emissions")
A12: =Merged_Dataset!A12 | B12: =Merged_Dataset!B12 | C12: =Merged_Dataset!H12 | D12: =Merged_Dataset!I12 | E12: =Merged_Dataset!J12 | F12: =Merged_Dataset!K12 | G12: =Merged_Dataset!C12 | H12: =Merged_Dataset!D12 | I12: =Merged_Dataset!E12 | J12: =Merged_Dataset!F12 | K12: =Merged_Dataset!G12 | L12: =Merged_Dataset!M12 | M12: =Merged_Dataset!S12 | N12: =Merged_Dataset!T12 | O12: =Merged_Dataset!U12 | P12: =Merged_Dataset!R12 | Q12: =Merged_Dataset!V12 | R12: =IF(O12="","Estimated calculation unavailable until coefficients and carbon intensity are supplied","Grid-intensity-based estimate; not provider-reported emissions")
A13: =Merged_Dataset!A13 | B13: =Merged_Dataset!B13 | C13: =Merged_Dataset!H13 | D13: =Merged_Dataset!I13 | E13: =Merged_Dataset!J13 | F13: =Merged_Dataset!K13 | G13: =Merged_Dataset!C13 | H13: =Merged_Dataset!D13 | I13: =Merged_Dataset!E13 | J13: =Merged_Dataset!F13 | K13: =Merged_Dataset!G13 | L13: =Merged_Dataset!M13 | M13: =Merged_Dataset!S13 | N13: =Merged_Dataset!T13 | O13: =Merged_Dataset!U13 | P13: =Merged_Dataset!R13 | Q13: =Merged_Dataset!V13 | R13: =IF(O13="","Estimated calculation unavailable until coefficients and carbon intensity are supplied","Grid-intensity-based estimate; not provider-reported emissions")
... A265: =Merged_Dataset!A265 | B265: =Merged_Dataset!B265 | C265: =Merged_Dataset!H265 | D265: =Merged_Dataset!I265 | E265: =Merged_Dataset!J265 | F265: =Merged_Dataset!K265 | G265: =Merged_Dataset!C265 | H265: =Merged_Dataset!D265 | I265: =Merged_Dataset!E265 | J265: =Merged_Dataset!F265 | K265: =Merged_Dataset!G265 | L265: =Merged_Dataset!M265 | M265: =Merged_Dataset!S265 | N265: =Merged_Dataset!T265 | O265: =Merged_Dataset!U265 | P265: =Merged_Dataset!R265 | Q265: =Merged_Dataset!V265 | R265: =IF(O265="","Estimated calculation unavailable until coefficients and carbon intensity are supplied","Grid-intensity-based estimate; not provider-reported emissions")

Sheet Calculation_Guide
A1: Step | B1: What to do | C1: Formula / rule | D1: Important limitation
A2: 1. Supply energy coefficients | B2: Enter validated values in Energy_Coefficients!B2:B5. | C2: Energy (kWh) = [(CPU utilization fraction × runtime × VM count × CPU coefficient) + (RAM GB × runtime × VM count × RAM coefficient) + (Storage GB × runtime × VM count × storage coefficient)] × PUE. | D2: The workbook intentionally leaves coefficients blank because no validated source values were supplied. Do not enter guessed values.
A3: 2. Supply carbon intensity | B3: Use a verified region-level grid carbon-intensity value in gCO2e/kWh. | C3: CO2e (g) = Energy (kWh) × carbon intensity (gCO2e/kWh); CO2e (kg) = CO2e (g) / 1000. | D3: GCP values in Carbon_Region_Data are provider-published regional metrics. AWS/Azure grid proxy values are not provider-reported emissions.
A4: 3. Review Final_Calculation | B4: Use this sheet as the merged final calculation table. Filter by provider, region, workload, and Calculation_Status. | C4: Rows link to Merged_Dataset and update when source inputs are added. | D4: Results are estimates based on project coefficients and grid intensity; they are not audited/provider-reported emissions.
A5: 4. For provider-reported emissions | B5: Paste normalized report rows into Provider_Emissions_Import. Keep provider, period, region, service, scope, unit, and report source. | C5: Compare only records with aligned reporting period, scope, and measurement basis. | D5: This workbook does not automatically convert imported provider reports into the grid-intensity estimate. Provider-reported emissions and grid-based estimates must be shown separately.
A6: 5. Renewable share / CFE | B6: Populate only when supported by a documented source and year. | C6: Can be used as a separate comparison metric; do not silently adjust CO2e unless methodology defines the adjustment. | D6: Renewable share and CFE are not interchangeable metrics.
A7: Option 1 regional comparison | B7: Option1_Region_Comparison is the canonical view for grid-intensity-based comparison across providers. GCP values use published 2025 regional metrics; AWS/Azure values are filled only where an explicitly labelled location-level proxy exists. Blank values are intentional. | C7: CO₂e (g) = Energy (kWh) × grid intensity (gCO₂e/kWh) | D7: Do not call grid proxy results provider-reported emissions.
A8: 5. Update regional grid factors | B8: Download the current Ember global CSV; use Ember India state-level CSV for Indian regions. Match the correct year and geography, then enter values in Ember_Grid_Factor_Import and Option1_Region_Comparison. | C8: Use Ember emissions intensity (gCO₂e/kWh) for the selected year and geography. | D8: The CSV download was not embedded in this workbook; factors remain blank until sourced and validated. Country/state factors are proxies for cloud-region grid supply, not provider-specific emissions.

Sheet Carbon_Region_Data
A1: Provider | B1: Region_Code | C1: Region | D1: Country | E1: Data_Status | F1: Carbon_Intensity_gCO2e_per_kWh | G1: Carbon_Intensity_kgCO2e_per_kWh | H1: CFE_% | I1: Source | J1: Data_Method | K1: Comparability_Note
A2: GCP | B2: africa-south1 | C2: Johannesburg | D2: South Africa | E2: 2025 published data | F2: 641 | G2: 0.641 | H2: 15 | I2: Google Cloud regional carbon page (2025 data) | J2: Provider-published 2025 regional metric | K2: Official Google Cloud regional value. Not directly comparable to AWS/Azure provider-specific emissions.
A3: GCP | B3: asia-east1 | C3: Taiwan | D3: Taiwan | E3: 2025 published data | F3: 428 | G3: 0.428 | H3: 15 | I3: Google Cloud regional carbon page (2025 data) | J3: Provider-published 2025 regional metric | K3: Official Google Cloud regional value. Not directly comparable to AWS/Azure provider-specific emissions.
A4: GCP | B4: asia-east2 | C4: Hong Kong | D4: Hong Kong | E4: 2025 published data | F4: 489 | G4: 0.489 | H4: 2 | I4: Google Cloud regional carbon page (2025 data) | J4: Provider-published 2025 regional metric | K4: Official Google Cloud regional value. Not directly comparable to AWS/Azure provider-specific emissions.
A5: GCP | B5: asia-northeast1 | C5: Tokyo | D5: Japan | E5: 2025 published data | F5: 449 | G5: 0.449 | H5: 23 | I5: Google Cloud regional carbon page (2025 data) | J5: Provider-published 2025 regional metric | K5: Official Google Cloud regional value. Not directly comparable to AWS/Azure provider-specific emissions.
A6: GCP | B6: asia-northeast2 | C6: Osaka | D6: Japan | E6: 2025 published data | F6: 299 | G6: 0.299 | H6: 45 | I6: Google Cloud regional carbon page (2025 data) | J6: Provider-published 2025 regional metric | K6: Official Google Cloud regional value. Not directly comparable to AWS/Azure provider-specific emissions.
A7: GCP | B7: asia-northeast3 | C7: Seoul | D7: South Korea | E7: 2025 published data | F7: 359 | G7: 0.359 | H7: 37 | I7: Google Cloud regional carbon page (2025 data) | J7: Provider-published 2025 regional metric | K7: Official Google Cloud regional value. Not directly comparable to AWS/Azure provider-specific emissions.
A8: GCP | B8: asia-south1 | C8: Mumbai | D8: India | E8: 2025 published data | F8: 598 | G8: 0.598 | H8: 20 | I8: Google Cloud regional carbon page (2025 data) | J8: Provider-published 2025 regional metric | K8: Official Google Cloud regional value. Not directly comparable to AWS/Azure provider-specific emissions.
A9: GCP | B9: asia-south2 | C9: Delhi | D9: India | E9: 2025 published data | F9: 473 | G9: 0.473 | H9: 39 | I9: Google Cloud regional carbon page (2025 data) | J9: Provider-published 2025 regional metric | K9: Official Google Cloud regional value. Not directly comparable to AWS/Azure provider-specific emissions.
A10: GCP | B10: asia-southeast1 | C10: Singapore | D10: Singapore | E10: 2025 published data | F10: 366 | G10: 0.366 | H10: 5 | I10: Google Cloud regional carbon page (2025 data) | J10: Provider-published 2025 regional metric | K10: Official Google Cloud regional value. Not directly comparable to AWS/Azure provider-specific emissions.
A11: GCP | B11: asia-southeast2 | C11: Jakarta | D11: Indonesia | E11: 2025 published data | F11: 588 | G11: 0.588 | H11: 15 | I11: Google Cloud regional carbon page (2025 data) | J11: Provider-published 2025 regional metric | K11: Official Google Cloud regional value. Not directly comparable to AWS/Azure provider-specific emissions.
A12: GCP | B12: australia-southeast1 | C12: Sydney | D12: Australia | E12: 2025 published data | F12: 468 | G12: 0.468 | H12: 37 | I12: Google Cloud regional carbon page (2025 data) | J12: Provider-published 2025 regional metric | K12: Official Google Cloud regional value. Not directly comparable to AWS/Azure provider-specific emissions.
A13: GCP | B13: australia-southeast2 | C13: Melbourne | D13: Australia | E13: 2025 published data | F13: 416 | G13: 0.416 | H13: 44 | I13: Google Cloud regional carbon page (2025 data) | J13: Provider-published 2025 regional metric | K13: Official Google Cloud regional value. Not directly comparable to AWS/Azure provider-specific emissions.
... A45: GCP | B45: us-west4 | C45: Las Vegas | D45: United States | E45: 2025 published data | F45: 360 | G45: 0.36 | H45: 65 | I45: Google Cloud regional carbon page (2025 data) | J45: Provider-published 2025 regional metric | K45: Official Google Cloud regional value. Not directly comparable to AWS/Azure provider-specific emissions.

Sheet Cloud_Regions
A1: Provider | B1: Region_Code | C1: Region | D1: Country | E1: Status
A2: GCP | B2: asia-south1 | C2: Mumbai | D2: India | E2: Published regional carbon data available where listed in Carbon_Region_Data
A3: GCP | B3: asia-south2 | C3: Delhi | D3: India | E3: Published regional carbon data available where listed in Carbon_Region_Data
A4: GCP | B4: asia-southeast1 | C4: Singapore | D4: Singapore | E4: Published regional carbon data available where listed in Carbon_Region_Data
A5: GCP | B5: us-east4 | C5: Northern Virginia | D5: United States | E5: Published regional carbon data available where listed in Carbon_Region_Data
A6: GCP | B6: us-central1 | C6: Iowa | D6: United States | E6: Published regional carbon data available where listed in Carbon_Region_Data
A7: GCP | B7: europe-north1 | C7: Finland | D7: Finland | E7: Published regional carbon data available where listed in Carbon_Region_Data
A8: GCP | B8: europe-north2 | C8: Stockholm | D8: Sweden | E8: Published regional carbon data available where listed in Carbon_Region_Data
A9: AWS | B9: af-south-1 | C9: Africa (Cape Town) | D9: South Africa | E9: Official region metadata; provider-reported emissions required
A10: AWS | B10: ap-east-1 | C10: Asia Pacific (Hong Kong) | D10: Hong Kong | E10: Official region metadata; provider-reported emissions required
A11: AWS | B11: ap-east-2 | C11: Asia Pacific (Taipei) | D11: Taiwan | E11: Official region metadata; provider-reported emissions required
A12: AWS | B12: ap-northeast-1 | C12: Asia Pacific (Tokyo) | D12: Japan | E12: Official region metadata; provider-reported emissions required
... A101: Azure | B101: taiwannorth | C101: Taiwan North | D101: Taiwan | E101: Official region metadata; provider-reported emissions required

Sheet Renewable_Electricity
A1: Country | B1: Data_Year | C1: Renewable_Share_% | D1: Source

Sheet Population_Density
A1: Country | B1: Data_Year | C1: People_per_sq_km | D1: Source

Sheet Energy_Coefficients
A1: Parameter | B1: Value | C1: Unit | D1: Status
A2: CPU dynamic power coefficient | C2: kWh per hour at specified utilization | D2: Not populated: requires validated source
A3: RAM power coefficient | C3: kWh per GB-hour | D3: Not populated: requires validated source
A4: Storage power coefficient | C4: kWh per GB-hour | D4: Not populated: requires validated source
A5: PUE | C5: dimensionless | D5: Not populated: use facility/provider-specific sourced value

Sheet Merged_Dataset
A1: Record_ID | B1: Workload_Type | C1: CPU_Utilization_% | D1: RAM_GB | E1: Storage_GB | F1: Runtime_Hours | G1: VM_Count | H1: Provider | I1: Region_Code | J1: Region | K1: Country | L1: Carbon_Data_Year | M1: Carbon_Intensity_gCO2e_per_kWh | N1: Renewable_Data_Year | O1: Renewable_Share_% | P1: Population_Data_Year | Q1: Population_per_sq_km | R1: CFE_% | S1: Energy_kWh | T1: CO2e_g | U1: CO2e_kg | V1: Calculation_Status
A2: 1 | B2: Web Application | C2: 25 | D2: 4 | E2: 50 | F2: 4 | G2: 1 | H2: GCP | I2: africa-south1 | J2: Johannesburg | K2: South Africa | L2: 2025 | M2: 641 | R2: 15 | S2: =IF(COUNT(Energy_Coefficients!$B$2:$B$5)<4,"Missing validated energy coefficients/PUE",IF(M2="","Missing carbon intensity","Calculated estimate")) | T2: =IF(OR(S2="",M2=""),"",S2*M2) | U2: =IF(T2="","",T2/1000) | V2: =IF(COUNT(Energy_Coefficients!$B$2:$B$5)<4,"Needs coefficients",IF(M2="","Needs carbon intensity","Estimated CO2e; not provider-reported"))
A3: 2 | B3: Web Application | C3: 50 | D3: 8 | E3: 100 | F3: 8 | G3: 1 | H3: GCP | I3: africa-south1 | J3: Johannesburg | K3: South Africa | L3: 2025 | M3: 641 | R3: 15 | S3: =IF(COUNT(Energy_Coefficients!$B$2:$B$5)<4,"Missing validated energy coefficients/PUE",IF(M3="","Missing carbon intensity","Calculated estimate")) | T3: =IF(OR(S3="",M3=""),"",S3*M3) | U3: =IF(T3="","",T3/1000) | V3: =IF(COUNT(Energy_Coefficients!$B$2:$B$5)<4,"Needs coefficients",IF(M3="","Needs carbon intensity","Estimated CO2e; not provider-reported"))
A4: 3 | B4: Database | C4: 60 | D4: 16 | E4: 250 | F4: 12 | G4: 1 | H4: GCP | I4: africa-south1 | J4: Johannesburg | K4: South Africa | L4: 2025 | M4: 641 | R4: 15 | S4: =IF(COUNT(Energy_Coefficients!$B$2:$B$5)<4,"Missing validated energy coefficients/PUE",IF(M4="","Missing carbon intensity","Calculated estimate")) | T4: =IF(OR(S4="",M4=""),"",S4*M4) | U4: =IF(T4="","",T4/1000) | V4: =IF(COUNT(Energy_Coefficients!$B$2:$B$5)<4,"Needs coefficients",IF(M4="","Needs carbon intensity","Estimated CO2e; not provider-reported"))
A5: 4 | B5: Analytics | C5: 75 | D5: 32 | E5: 500 | F5: 24 | G5: 2 | H5: GCP | I5: africa-south1 | J5: Johannesburg | K5: South Africa | L5: 2025 | M5: 641 | R5: 15 | S5: =IF(COUNT(Energy_Coefficients!$B$2:$B$5)<4,"Missing validated energy coefficients/PUE",IF(M5="","Missing carbon intensity","Calculated estimate")) | T5: =IF(OR(S5="",M5=""),"",S5*M5) | U5: =IF(T5="","",T5/1000) | V5: =IF(COUNT(Energy_Coefficients!$B$2:$B$5)<4,"Needs coefficients",IF(M5="","Needs carbon intensity","Estimated CO2e; not provider-reported"))
A6: 5 | B6: ML Inference | C6: 80 | D6: 16 | E6: 250 | F6: 10 | G6: 2 | H6: GCP | I6: africa-south1 | J6: Johannesburg | K6: South Africa | L6: 2025 | M6: 641 | R6: 15 | S6: =IF(COUNT(Energy_Coefficients!$B$2:$B$5)<4,"Missing validated energy coefficients/PUE",IF(M6="","Missing carbon intensity","Calculated estimate")) | T6: =IF(OR(S6="",M6=""),"",S6*M6) | U6: =IF(T6="","",T6/1000) | V6: =IF(COUNT(Energy_Coefficients!$B$2:$B$5)<4,"Needs coefficients",IF(M6="","Needs carbon intensity","Estimated CO2e; not provider-reported"))
A7: 6 | B7: Batch Processing | C7: 90 | D7: 32 | E7: 1000 | F7: 18 | G7: 3 | H7: GCP | I7: africa-south1 | J7: Johannesburg | K7: South Africa | L7: 2025 | M7: 641 | R7: 15 | S7: =IF(COUNT(Energy_Coefficients!$B$2:$B$5)<4,"Missing validated energy coefficients/PUE",IF(M7="","Missing carbon intensity","Calculated estimate")) | T7: =IF(OR(S7="",M7=""),"",S7*M7) | U7: =IF(T7="","",T7/1000) | V7: =IF(COUNT(Energy_Coefficients!$B$2:$B$5)<4,"Needs coefficients",IF(M7="","Needs carbon intensity","Estimated CO2e; not provider-reported"))
A8: 1 | B8: Web Application | C8: 25 | D8: 4 | E8: 50 | F8: 4 | G8: 1 | H8: GCP | I8: asia-east1 | J8: Taiwan | K8: Taiwan | L8: 2025 | M8: 428 | R8: 15 | S8: =IF(COUNT(Energy_Coefficients!$B$2:$B$5)<4,"Missing validated energy coefficients/PUE",IF(M8="","Missing carbon intensity","Calculated estimate")) | T8: =IF(OR(S8="",M8=""),"",S8*M8) | U8: =IF(T8="","",T8/1000) | V8: =IF(COUNT(Energy_Coefficients!$B$2:$B$5)<4,"Needs coefficients",IF(M8="","Needs carbon intensity","Estimated CO2e; not provider-reported"))
A9: 2 | B9: Web Application | C9: 50 | D9: 8 | E9: 100 | F9: 8 | G9: 1 | H9: GCP | I9: asia-east1 | J9: Taiwan | K9: Taiwan | L9: 2025 | M9: 428 | R9: 15 | S9: =IF(COUNT(Energy_Coefficients!$B$2:$B$5)<4,"Missing validated energy coefficients/PUE",IF(M9="","Missing carbon intensity","Calculated estimate")) | T9: =IF(OR(S9="",M9=""),"",S9*M9) | U9: =IF(T9="","",T9/1000) | V9: =IF(COUNT(Energy_Coefficients!$B$2:$B$5)<4,"Needs coefficients",IF(M9="","Needs carbon intensity","Estimated CO2e; not provider-reported"))
A10: 3 | B10: Database | C10: 60 | D10: 16 | E10: 250 | F10: 12 | G10: 1 | H10: GCP | I10: asia-east1 | J10: Taiwan | K10: Taiwan | L10: 2025 | M10: 428 | R10: 15 | S10: =IF(COUNT(Energy_Coefficients!$B$2:$B$5)<4,"Missing validated energy coefficients/PUE",IF(M10="","Missing carbon intensity","Calculated estimate")) | T10: =IF(OR(S10="",M10=""),"",S10*M10) | U10: =IF(T10="","",T10/1000) | V10: =IF(COUNT(Energy_Coefficients!$B$2:$B$5)<4,"Needs coefficients",IF(M10="","Needs carbon intensity","Estimated CO2e; not provider-reported"))
A11: 4 | B11: Analytics | C11: 75 | D11: 32 | E11: 500 | F11: 24 | G11: 2 | H11: GCP | I11: asia-east1 | J11: Taiwan | K11: Taiwan | L11: 2025 | M11: 428 | R11: 15 | S11: =IF(COUNT(Energy_Coefficients!$B$2:$B$5)<4,"Missing validated energy coefficients/PUE",IF(M11="","Missing carbon intensity","Calculated estimate")) | T11: =IF(OR(S11="",M11=""),"",S11*M11) | U11: =IF(T11="","",T11/1000) | V11: =IF(COUNT(Energy_Coefficients!$B$2:$B$5)<4,"Needs coefficients",IF(M11="","Needs carbon intensity","Estimated CO2e; not provider-reported"))
A12: 5 | B12: ML Inference | C12: 80 | D12: 16 | E12: 250 | F12: 10 | G12: 2 | H12: GCP | I12: asia-east1 | J12: Taiwan | K12: Taiwan | L12: 2025 | M12: 428 | R12: 15 | S12: =IF(COUNT(Energy_Coefficients!$B$2:$B$5)<4,"Missing validated energy coefficients/PUE",IF(M12="","Missing carbon intensity","Calculated estimate")) | T12: =IF(OR(S12="",M12=""),"",S12*M12) | U12: =IF(T12="","",T12/1000) | V12: =IF(COUNT(Energy_Coefficients!$B$2:$B$5)<4,"Needs coefficients",IF(M12="","Needs carbon intensity","Estimated CO2e; not provider-reported"))
A13: 6 | B13: Batch Processing | C13: 90 | D13: 32 | E13: 1000 | F13: 18 | G13: 3 | H13: GCP | I13: asia-east1 | J13: Taiwan | K13: Taiwan | L13: 2025 | M13: 428 | R13: 15 | S13: =IF(COUNT(Energy_Coefficients!$B$2:$B$5)<4,"Missing validated energy coefficients/PUE",IF(M13="","Missing carbon intensity","Calculated estimate")) | T13: =IF(OR(S13="",M13=""),"",S13*M13) | U13: =IF(T13="","",T13/1000) | V13: =IF(COUNT(Energy_Coefficients!$B$2:$B$5)<4,"Needs coefficients",IF(M13="","Needs carbon intensity","Estimated CO2e; not provider-reported"))
... A265: 6 | B265: Batch Processing | C265: 90 | D265: 32 | E265: 1000 | F265: 18 | G265: 3 | H265: GCP | I265: us-west4 | J265: Las Vegas | K265: United States | L265: 2025 | M265: 360 | R265: 65 | S265: =IF(COUNT(Energy_Coefficients!$B$2:$B$5)<4,"Missing validated energy coefficients/PUE",IF(M265="","Missing carbon intensity","Calculated estimate")) | T265: =IF(OR(S265="",M265=""),"",S265*M265) | U265: =IF(T265="","",T265/1000) | V265: =IF(COUNT(Energy_Coefficients!$B$2:$B$5)<4,"Needs coefficients",IF(M265="","Needs carbon intensity","Estimated CO2e; not provider-reported"))

Sheet Sources
A1: Dataset/Source | B1: URL | C1: Use in project / limitation
A2: Google Cloud regional carbon data (2025; regional grid intensity and CFE%) | B2: https://cloud.google.com/sustainability/region-carbon | C2: Region metadata or supplementary source; confirm the exact dataset, geography, year, and measurement basis before using values.
A3: AWS official regions and geography (region names/locations only) | B3: https://docs.aws.amazon.com/global-infrastructure/latest/regions/aws-regions.html | C3: Region metadata or supplementary source; confirm the exact dataset, geography, year, and measurement basis before using values.
A4: Azure official regions and physical locations (region names/locations only) | B4: https://learn.microsoft.com/en-us/azure/reliability/regions-list | C4: Region metadata or supplementary source; confirm the exact dataset, geography, year, and measurement basis before using values.
A5: Ember yearly electricity data (open country-level electricity/emissions dataset; separate download needed for national factors) | B5: https://ember-energy.org/data/yearly-electricity-data/ | C5: Region metadata or supplementary source; confirm the exact dataset, geography, year, and measurement basis before using values.
A6: AWS sustainability methodology (provider-reported emissions methodology; not the source of grid proxy values) | B6: https://docs.aws.amazon.com/sustainability/latest/userguide/methodology.html | C6: Region metadata or supplementary source; confirm the exact dataset, geography, year, and measurement basis before using values.
A7: Microsoft Azure emissions methodology (provider-reported emissions methodology; not the source of grid proxy values) | B7: https://learn.microsoft.com/en-us/power-bi/connect-data/azure-emissions-calculation-methodology | C7: Region metadata or supplementary source; confirm the exact dataset, geography, year, and measurement basis before using values.
A8: AWS official region catalog | B8: https://docs.aws.amazon.com/global-infrastructure/latest/regions/aws-regions.html | C8: Region metadata or supplementary source; confirm the exact dataset, geography, year, and measurement basis before using values.
A9: Azure official public region catalog | B9: https://learn.microsoft.com/en-us/azure/reliability/regions-list | C9: Region metadata or supplementary source; confirm the exact dataset, geography, year, and measurement basis before using values.
A10: AWS Sustainability CSV reports | B10: https://docs.aws.amazon.com/sustainability/latest/userguide/csv-reports.html | C10: Region metadata or supplementary source; confirm the exact dataset, geography, year, and measurement basis before using values.
A11: Azure Carbon Optimization | B11: https://learn.microsoft.com/en-us/azure/carbon-optimization/overview | C11: Region metadata or supplementary source; confirm the exact dataset, geography, year, and measurement basis before using values.
A12: GCP Carbon Footprint export | B12: https://docs.cloud.google.com/carbon-footprint/docs/export | C12: Region metadata or supplementary source; confirm the exact dataset, geography, year, and measurement basis before using values.
... A18: Ember India Electricity Data (state/UT level) | B18: https://ember-energy.org/data/india-electricity-data/ | C18: State/UT-level electricity carbon intensity for 36 Indian geographies. Use state-level factors for Indian cloud regions where available.

Sheet Cross_Provider_Grid_Map
A1: Provider | B1: Region_Code | C1: Region | D1: Country | E1: Status | F1: Grid_Intensity_Available | G1: Grid_Intensity_gCO2e_per_kWh | H1: Data_Type | I1: Source/Method note
A2: AWS | B2: ap-south-1 | C2: Mumbai | D2: India | E2: Metadata only - no verified matching grid value | F2: FALSE | H2: Unavailable - left blank | I2: No sufficiently verified same-location grid value in the current workbook; do not estimate or substitute.
A3: AWS | B3: ap-south-2 | C3: Hyderabad | D3: India | E3: Metadata only - no verified matching grid value | F3: FALSE | H3: Unavailable - left blank | I3: No sufficiently verified same-location grid value in the current workbook; do not estimate or substitute.
A4: AWS | B4: ap-southeast-1 | C4: Singapore | D4: Singapore | E4: Published grid value mapped (location proxy) | F4: TRUE | G4: 366 | H4: Mapped location-level grid proxy (not provider emissions) | I4: Mapped published grid-intensity value from GCP location Singapore (asia-southeast1); used as location-level grid proxy only, not AWS/Azure provider emissions
A5: AWS | B5: us-east-1 | C5: N. Virginia | D5: United States | E5: Published grid value mapped (location proxy) | F5: TRUE | G5: 343 | H5: Mapped location-level grid proxy (not provider emissions) | I5: Mapped published grid-intensity value from GCP location Northern Virginia (us-east4); used as location-level grid proxy only, not AWS/Azure provider emissions
A6: AWS | B6: us-west-2 | C6: Oregon | D6: United States | E6: Published grid value mapped (location proxy) | F6: TRUE | G6: 98 | H6: Mapped location-level grid proxy (not provider emissions) | I6: Mapped published grid-intensity value from GCP location Oregon (us-west1); used as location-level grid proxy only, not AWS/Azure provider emissions
A7: Azure | B7: centralindia | C7: Pune | D7: India | E7: Metadata only - no verified matching grid value | F7: FALSE | H7: Unavailable - left blank | I7: No sufficiently verified same-location grid value in the current workbook; do not estimate or substitute.
A8: Azure | B8: indiasouthcentral | C8: Hyderabad | D8: India | E8: Metadata only - no verified matching grid value | F8: FALSE | H8: Unavailable - left blank | I8: No sufficiently verified same-location grid value in the current workbook; do not estimate or substitute.
A9: Azure | B9: southindia | C9: Chennai | D9: India | E9: Metadata only - no verified matching grid value | F9: FALSE | H9: Unavailable - left blank | I9: No sufficiently verified same-location grid value in the current workbook; do not estimate or substitute.
A10: Azure | B10: westindia | C10: Mumbai | D10: India | E10: Metadata only - no verified matching grid value | F10: TRUE | G10: 598 | H10: Mapped location-level grid proxy (not provider emissions) | I10: Mapped published grid-intensity value from GCP location Mumbai (asia-south1); used as location-level grid proxy only, not AWS/Azure provider emissions
A11: Azure | B11: southeastasia | C11: Singapore | D11: Singapore | E11: Metadata only - no verified matching grid value | F11: TRUE | G11: 366 | H11: Mapped location-level grid proxy (not provider emissions) | I11: Mapped published grid-intensity value from GCP location Singapore (asia-southeast1); used as location-level grid proxy only, not AWS/Azure provider emissions
A12: Azure | B12: eastus | C12: Virginia | D12: United States | E12: Metadata only - no verified matching grid value | F12: FALSE | H12: Unavailable - left blank | I12: No sufficiently verified same-location grid value in the current workbook; do not estimate or substitute.
A13: GCP | B13: asia-south1 | C13: Mumbai | D13: India | E13: Current | F13: TRUE | G13: 598 | H13: Published GCP regional value | I13: Provider-published 2025 regional metric
A14: GCP | B14: asia-south2 | C14: Delhi | D14: India | E14: Current | F14: TRUE | G14: 473 | H14: Published GCP regional value | I14: Provider-published 2025 regional metric
A15: GCP | B15: asia-southeast1 | C15: Singapore | D15: Singapore | E15: Current | F15: TRUE | G15: 366 | H15: Published GCP regional value | I15: Provider-published 2025 regional metric
A16: GCP | B16: us-east4 | C16: Northern Virginia | D16: United States | E16: Current | F16: TRUE | G16: 343 | H16: Published GCP regional value | I16: Provider-published 2025 regional metric
A17: GCP | B17: us-central1 | C17: Iowa | D17: United States | E17: Current | F17: TRUE | G17: 432 | H17: Published GCP regional value | I17: Provider-published 2025 regional metric
A18: GCP | B18: europe-north1 | C18: Finland | D18: Finland | E18: Current | F18: TRUE | G18: 30 | H18: Published GCP regional value | I18: Provider-published 2025 regional metric
A19: GCP | B19: europe-north2 | C19: Stockholm | D19: Sweden | E19: Current | F19: TRUE | G19: 19 | H19: Published GCP regional value | I19: Provider-published 2025 regional metric
A20: AWS | B20: af-south-1 | C20: Africa (Cape Town) | D20: South Africa | E20: Region metadata only - no verified location grid factor | F20: FALSE | H20: Unavailable - left blank | I20: Option 1 requires a verified grid-intensity factor for this location and matching period. No value inferred from country or another provider.
A21: AWS | B21: ap-east-1 | C21: Asia Pacific (Hong Kong) | D21: Hong Kong | E21: Region metadata only - no verified location grid factor | F21: FALSE | H21: Unavailable - left blank | I21: Option 1 requires a verified grid-intensity factor for this location and matching period. No value inferred from country or another provider.
